<?xml version="1.0" encoding="utf-8"?>
<!-- =================================================================================== -->
<!-- |    This document was autogenerated by xacro from panda_arm_hand.urdf.xacro      | -->
<!-- |    EDITING THIS FILE BY HAND IS NOT RECOMMENDED                                 | -->
<!-- =================================================================================== -->
<robot name="panda">
  <!-- If using a different frame with ${connected_to} param, make sure 'world' frame exists in the TF tree -->
  <link name="world"/>
  <joint name="panda_to_world" type="fixed">
    <parent link="world"/>
    <child link="panda_link0"/>
    <origin rpy="0 0 0" xyz="0 0 0"/>
  </joint>
  <link name="panda_link0">
    <visual>
      <geometry>
        <mesh filename="package://franka_panda_description/meshes/visual/link0.dae"/>
      </geometry>
    </visual>
    <collision>
      <geometry>
        <mesh filename="package://franka_panda_description/meshes/collision/link0.stl"/>
      </geometry>
    </collision>
  </link>
  <link name="panda_link1">
    <visual>
      <geometry>
        <mesh filename="package://franka_panda_description/meshes/visual/link1.dae"/>
      </geometry>
    </visual>
    <collision>
      <geometry>
        <mesh filename="package://franka_panda_description/meshes/collision/link1.stl"/>
      </geometry>
    </collision>
    <inertial>
      <origin rpy="0 0 0" xyz="3.875e-03 2.081e-03 -0.1750"/>
      <mass value="4.970684"/>
      <inertia ixx="7.0337e-01" ixy="-1.3900e-04" ixz="6.7720e-03" iyy="7.0661e-01" iyz="1.9169e-02" izz="9.1170e-03"/>
    </inertial>
  </link>
  <joint name="panda_joint1" type="revolute">
    <safety_controller k_position="100.0" k_velocity="40.0" soft_lower_limit="-2.8973" soft_upper_limit="2.8973"/>
    <origin rpy="0 0 0" xyz="0 0 0.333"/>
    <parent link="panda_link0"/>
    <child link="panda_link1"/>
    <axis xyz="0 0 1"/>
    <limit effort="87" lower="-2.8973" upper="2.8973" velocity="2.1750"/>
    <dynamics damping="10.0" friction="5.0"/>
  </joint>
  <link name="panda_link2">
    <visual>
      <geometry>
        <mesh filename="package://franka_panda_description/meshes/visual/link2.dae"/>
      </geometry>
    </visual>
    <collision>
      <geometry>
        <mesh filename="package://franka_panda_description/meshes/collision/link2.stl"/>
      </geometry>
    </collision>
    <inertial>
      <origin rpy="0 0 0" xyz="-3.141e-03 -2.872e-02 3.495e-03"/>
      <mass value="0.646926"/>
      <inertia ixx="7.9620e-03" ixy="-3.9250e-03" ixz="1.0254e-02" iyy="2.8110e-02" iyz="7.0400e-04" izz="2.5995e-02"/>
    </inertial>
  </link>
  <joint name="panda_joint2" type="revolute">
    <!-- <safety_controller k_position="100.0" k_velocity="40.0" soft_lower_limit="-1.7628" soft_upper_limit="1.7628"/> -->
    <safety_controller k_position="100.0" k_velocity="40.0" soft_lower_limit="-1.8317" soft_upper_limit="1.8317"/>
    <origin rpy="-1.57079632679 0 0" xyz="0 0 0"/>
    <parent link="panda_link1"/>
    <child link="panda_link2"/>
    <axis xyz="0 0 1"/>
    <limit effort="87" lower="-1.7628" upper="1.7628" velocity="2.1750"/>
    <dynamics damping="5.0" friction="2.0"/>
  </joint>
  <link name="panda_link3">
    <visual>
      <geometry>
        <mesh filename="package://franka_panda_description/meshes/visual/link3.dae"/>
      </geometry>
    </visual>
    <collision>
      <geometry>
        <mesh filename="package://franka_panda_description/meshes/collision/link3.stl"/>
      </geometry>
    </collision>
    <inertial>
      <origin rpy="0 0 0" xyz="2.7518e-02 3.9252e-02 -6.6502e-02"/>
      <mass value="3.228604"/>
      <inertia ixx="3.7242e-02" ixy="-4.7610e-03" ixz="-1.1396e-02" iyy="3.6155e-02" iyz="-1.2805e-02" izz="1.0830e-02"/>
    </inertial>
  </link>
  <joint name="panda_joint3" type="revolute">
    <safety_controller k_position="100.0" k_velocity="40.0" soft_lower_limit="-2.8973" soft_upper_limit="2.8973"/>
    <origin rpy="1.57079632679 0 0" xyz="0 -0.316 0"/>
    <parent link="panda_link2"/>
    <child link="panda_link3"/>
    <axis xyz="0 0 1"/>
    <limit effort="87" lower="-2.8973" upper="2.8973" velocity="2.1750"/>
    <dynamics damping="5.0" friction="2.0"/>
  </joint>
  <link name="panda_link4">
    <visual>
      <geometry>
        <mesh filename="package://franka_panda_description/meshes/visual/link4.dae"/>
      </geometry>
    </visual>
    <collision>
      <geometry>
        <mesh filename="package://franka_panda_description/meshes/collision/link4.stl"/>
      </geometry>
    </collision>
    <inertial>
      <origin rpy="0 0 0" xyz="-5.317e-02 1.04419e-01 2.7454e-02"/>
      <mass value="3.587895"/>
      <inertia ixx="2.5853e-02" ixy="7.7960e-03" ixz="-1.3320e-03" iyy="1.9552e-02" iyz="8.6410e-03" izz="2.8323e-02"/>
    </inertial>
  </link>
  <joint name="panda_joint4" type="revolute">
    <!-- <safety_controller k_position="100.0" k_velocity="40.0" soft_lower_limit="-3.0718" soft_upper_limit="-0.0698"/> -->
    <safety_controller k_position="100.0" k_velocity="40.0" soft_lower_limit="-3.0718" soft_upper_limit="-0.1221"/>
    <origin rpy="1.57079632679 0 0" xyz="0.0825 0 0"/>
    <parent link="panda_link3"/>
    <child link="panda_link4"/>
    <axis xyz="0 0 1"/>
    <limit effort="87" lower="-3.0718" upper="-0.0698" velocity="2.1750"/>
    <dynamics damping="1.0" friction="0.5"/>
  </joint>
  <link name="panda_link5">
    <visual>
      <geometry>
        <mesh filename="package://franka_panda_description/meshes/visual/link5.dae"/>
      </geometry>
    </visual>
    <collision>
      <geometry>
        <mesh filename="package://franka_panda_description/meshes/collision/link5.stl"/>
      </geometry>
    </collision>
    <inertial>
      <origin rpy="0 0 0" xyz="-1.1953e-02 4.1065e-02 -3.8437e-02"/>
      <mass value="1.225946"/>
      <inertia ixx="3.5549e-02" ixy="-2.1170e-03" ixz="-4.0370e-03" iyy="2.9474e-02" iyz="2.2900e-04" izz="8.6270e-03"/>
    </inertial>
  </link>
  <joint name="panda_joint5" type="revolute">
    <safety_controller k_position="100.0" k_velocity="40.0" soft_lower_limit="-2.8973" soft_upper_limit="2.8973"/>
    <origin rpy="-1.57079632679 0 0" xyz="-0.0825 0.384 0"/>
    <parent link="panda_link4"/>
    <child link="panda_link5"/>
    <axis xyz="0 0 1"/>
    <limit effort="12" lower="-2.8973" upper="2.8973" velocity="2.6100"/>
    <dynamics damping="2.0" friction="1.0"/>
  </joint>
  <link name="panda_link6">
    <visual>
      <geometry>
        <mesh filename="package://franka_panda_description/meshes/visual/link6.dae"/>
      </geometry>
    </visual>
    <collision>
      <geometry>
        <mesh filename="package://franka_panda_description/meshes/collision/link6.stl"/>
      </geometry>
    </collision>
    <inertial>
      <origin rpy="0 0 0" xyz="6.0149e-02 -1.4117e-02 -1.0517e-02"/>
      <mass value="1.666555"/>
      <inertia ixx="1.9640e-03" ixy="1.0900e-04" ixz="-1.1580e-03" iyy="4.3540e-03" iyz="3.4100e-04" izz="5.4330e-03"/>
    </inertial>
  </link>
  <joint name="panda_joint6" type="revolute">
    <!-- <safety_controller k_position="100.0" k_velocity="40.0" soft_lower_limit="-0.0175" soft_upper_limit="3.7525"/> -->
    <safety_controller k_position="100.0" k_velocity="40.0" soft_lower_limit="0.4361" soft_upper_limit="4.6228"/>
    <origin rpy="1.57079632679 0 0" xyz="0 0 0"/>
    <parent link="panda_link5"/>
    <child link="panda_link6"/>
    <axis xyz="0 0 1"/>
    <limit effort="12" lower="-0.0175" upper="3.7525" velocity="2.6100"/>
    <dynamics damping="1.0" friction="0.5"/>
  </joint>
  <link name="panda_link7">
    <visual>
      <geometry>
        <mesh filename="package://franka_panda_description/meshes/visual/link7.dae"/>
      </geometry>
    </visual>
    <collision>
      <geometry>
        <mesh filename="package://franka_panda_description/meshes/collision/link7.stl"/>
      </geometry>
    </collision>
    <inertial>
      <origin rpy="0 0 0" xyz="1.0517e-02 -4.252e-03 6.1597e-02"/>
      <mass value="7.35522e-01"/>
      <inertia ixx="1.2516e-02" ixy="-4.2800e-04" ixz="-1.1960e-03" iyy="1.0027e-02" iyz="-7.4100e-04" izz="4.8150e-03"/>
    </inertial>
  </link>
  <joint name="panda_joint7" type="revolute">
    <!-- <safety_controller k_position="100.0" k_velocity="40.0" soft_lower_limit="-2.8973" soft_upper_limit="2.8973"/> -->
    <safety_controller k_position="100.0" k_velocity="40.0" soft_lower_limit="-3.0528" soft_upper_limit="3.0528"/>
    <origin rpy="1.57079632679 0 0" xyz="0.088 0 0"/>
    <parent link="panda_link6"/>
    <child link="panda_link7"/>
    <axis xyz="0 0 1"/>
    <limit effort="12" lower="-2.8973" upper="2.8973" velocity="2.6100"/>
    <dynamics damping="1.0" friction="0.5"/>
  </joint>
  <link name="panda_link8">
    <inertial>
      <origin rpy="0 0 0" xyz="0 0 0"/>
      <mass value="0.01"/>
      <inertia ixx="0.001" ixy="0.0" ixz="0.0" iyy="0.001" iyz="0.0" izz="0.001"/>
    </inertial>
  </link>
  <joint name="panda_joint8" type="fixed">
    <origin rpy="0 0 0" xyz="0 0 0.107"/>
    <parent link="panda_link7"/>
    <child link="panda_link8"/>
    <axis xyz="0 0 0"/>
  </joint>

  <!-- robotiq 2f-85 gripper -->
  <joint name="panda_robotiq_attachment_joint" type="fixed">    
    <origin xyz="0 0 0" rpy="0 0 0.0"/>
    <parent link="panda_link8"/>
    <child link="robotiq_85_base_link"/>
    <axis xyz="0 0 0"/>
  </joint>  
  <link name="robotiq_85_base_link">
    <inertial>
      <origin xyz="0.00021987 -2.3546E-10 0.030163" rpy="0 0 0" />
      <!-- <mass value="0.30915" /> -->
      <mass value="0.79501" /> <!-- add robotiq attachment mass, so total gripper mass should be 0.9kg -->
      <inertia ixx="0.00028972" ixy="-5.7879E-10" ixz="-1.8543E-06" iyy="0.00030737" iyz="1.682E-12" izz="0.00019914"/>
    </inertial>
    <visual>
      <origin xyz="0 0 0" rpy="0 0 0" />
      <geometry>
        <!-- <mesh filename="package://kimm_robotiq_2f_85_description/meshes/visual/robotiq_arg2f_85_base_link.dae" scale="0.001 0.001 0.001"/> -->
        <mesh filename="package://kimm_robotiq_2f_85_description/meshes_aprice/robotiq_85_base_link_fine.STL"/>
      </geometry>
      <material name="">
        <color rgba="0.1 0.1 0.1 1" />
      </material>
    </visual>
    <collision>
      <origin xyz="0 0 0" rpy="0 0 0" />
      <geometry>
        <!-- <mesh filename="package://kimm_robotiq_2f_85_description/meshes/collision/robotiq_arg2f_85_base_link.stl"/> -->
        <mesh filename="package://kimm_robotiq_2f_85_description/meshes_aprice/robotiq_85_base_link_coarse.STL"/>
      </geometry>
    </collision>
  </link>
  <link name="left_outer_knuckle">
    <inertial>
      <origin
        xyz="0.0178331863169983 3.68915177224286E-11 0.0021442477325704" rpy="0 0 0" />
      <mass value="0.00684838849434396" />
      <inertia ixx="2.66832029033166E-07" ixy="1.66142314639824E-15" ixz="1.45945633322873E-07" iyy="1.3889233257419E-06" iyz="2.82951161241588E-15" izz="1.26603336914415E-06"/>
    </inertial>
    <visual>
      <origin xyz="0 0 0" rpy="0 0 0" />
      <geometry>
        <!-- <mesh filename="package://kimm_robotiq_2f_85_description/meshes/visual/robotiq_arg2f_85_outer_knuckle.dae" scale="0.001 0.001 0.001"/> -->
        <mesh filename="package://kimm_robotiq_2f_85_description/meshes_aprice/outer_knuckle_fine.STL"/>
      </geometry>
      <material name="">
        <color rgba="0.1 0.1 0.1 1" />
      </material>
    </visual>
    <collision>
      <origin xyz="0 0 0" rpy="0 0 0" />
      <geometry>
        <!-- <mesh filename="package://kimm_robotiq_2f_85_description/meshes/collision/robotiq_arg2f_85_outer_knuckle.dae" scale="0.001 0.001 0.001"/> -->
        <mesh filename="package://kimm_robotiq_2f_85_description/meshes_aprice/outer_knuckle_coarse.STL"/>
      </geometry>
    </collision>
  </link>
  <joint name="finger_joint" type="revolute">
    <origin xyz="0.0306011444260539 0 0.0627920162695395" rpy="0 0 0" />
    <parent link="robotiq_85_base_link" />
    <child link="left_outer_knuckle" />
    <axis xyz="0 -1 0" />
    <limit lower="0" upper="0.725" velocity="2.0" effort="1000" />
  </joint>
  <link name="left_outer_finger">
    <inertial>
      <origin xyz="0.00131451599174296 2.88942057994543E-15 0.0215404163180413" rpy="0 0 0" />
      <mass value="0.0273093985570947" />
      <inertia ixx="8.51629628283022E-06" ixy="2.58174336207405E-19" ixz="3.83829504344079E-07" iyy="6.9133328065108E-06" iyz="-7.58589926143789E-19" izz="2.25006832221981E-06"/>
    </inertial>
    <visual>
      <origin xyz="0 0 0" rpy="0 0 0" />
      <geometry>
        <!-- <mesh filename="package://kimm_robotiq_2f_85_description/meshes/visual/robotiq_arg2f_85_outer_finger.dae" scale="0.001 0.001 0.001"/> -->
        <mesh filename="package://kimm_robotiq_2f_85_description/meshes_aprice/outer_finger_fine.STL"/>
      </geometry>
      <material name="">
        <color rgba="0.1 0.1 0.1 1" />
      </material>
    </visual>
    <collision>
      <origin xyz="0 0 0" rpy="0 0 0" />
      <geometry>
        <!-- <mesh filename="package://kimm_robotiq_2f_85_description/meshes/collision/robotiq_arg2f_85_outer_finger.dae" scale="0.001 0.001 0.001"/> -->
        <mesh filename="package://kimm_robotiq_2f_85_description/meshes_aprice/outer_finger_coarse.STL"/>
      </geometry>
    </collision>
  </link>
  <joint name="left_outer_finger_joint" type="fixed">
    <origin xyz="0.0316910442266543 0 -0.00193396375724605" rpy="0 0 0" />
    <parent link="left_outer_knuckle" />
    <child link="left_outer_finger" />
    <axis xyz="0 -1 0" />
  </joint>
  <link name="left_inner_knuckle">
    <inertial>
      <origin xyz="0.017097546626628 -3.93808524389535E-10 0.0224918438201868" rpy="0 0 0" />
      <mass value="0.0110930853895903" />
      <inertia ixx="4.23392770691541E-06" ixy="5.748978936968E-15" ixz="1.78855677119788E-06" iyy="3.96548790524392E-06" iyz="1.05464666369669E-14" izz="3.24068002883007E-06"/>
    </inertial>
    <visual>
      <origin
        xyz="0 0 0" rpy="0 0 0" />
      <geometry>
        <!-- <mesh filename="package://kimm_robotiq_2f_85_description/meshes/visual/robotiq_arg2f_85_inner_knuckle.dae" scale="0.001 0.001 0.001"/> -->
        <mesh filename="package://kimm_robotiq_2f_85_description/meshes_aprice/inner_knuckle_fine.STL"/>
      </geometry>
      <material name="">
        <color rgba="0.1 0.1 0.1 1" />
      </material>
    </visual>
    <collision>
      <origin xyz="0 0 0" rpy="0 0 0" />
      <geometry>
        <!-- <mesh filename="package://kimm_robotiq_2f_85_description/meshes/collision/robotiq_arg2f_85_inner_knuckle.dae" scale="0.001 0.001 0.001"/> -->
        <mesh filename="package://kimm_robotiq_2f_85_description/meshes_aprice/inner_knuckle_coarse.STL"/>
      </geometry>
    </collision>
  </link>
  <joint name="left_inner_knuckle_joint" type="revolute">
    <origin xyz="0.0127000000001501 0 0.0693074999999639" rpy="0 0 0" />
    <parent link="robotiq_85_base_link" />
    <child link="left_inner_knuckle" />
    <axis xyz="0 -1 0" />
    <limit lower="0" upper="0.8757" velocity="2.0" effort="1000" />
    <mimic  joint="finger_joint" multiplier="1" offset="0" />
  </joint>
  <link name="left_inner_finger">
    <inertial>
      <origin xyz="0.0060275613594574 -6.29183141465421E-15 0.00669925693133241" rpy="0 0 0" />
      <mass value="0.00724255346165745" />
      <inertia ixx="1.47824274053603E-06" ixy="-3.94884463570303E-19" ixz="-3.45268847648622E-07" iyy="1.70064480838395E-06" iyz="3.5059838910097E-19" izz="4.77151336838364E-07"/>
    </inertial>
    <visual>
      <origin xyz="0 0 0" rpy="0 0 0" />
      <geometry>
        <!-- <mesh filename="package://kimm_robotiq_2f_85_description/meshes/visual/robotiq_arg2f_85_inner_finger.dae" scale="0.001 0.001 0.001"/> -->
        <mesh filename="package://kimm_robotiq_2f_85_description/meshes_aprice/inner_finger_fine.STL"/>
      </geometry>
      <material name="">
        <color rgba="0.1 0.1 0.1 1" />
      </material>
    </visual>
    <collision>
      <origin xyz="0 0 0" rpy="0 0 0" />
      <geometry>
        <!-- <mesh filename="package://kimm_robotiq_2f_85_description/meshes/collision/robotiq_arg2f_85_inner_finger.dae" scale="0.001 0.001 0.001"/> -->
        <mesh filename="package://kimm_robotiq_2f_85_description/meshes_aprice/inner_finger_coarse.STL"/>
      </geometry>
    </collision>
  </link>
  <joint name="left_inner_finger_joint" type="revolute">
    <origin xyz="0.034585310861294 0 0.0454970193817975" rpy="0 0 0" />
    <parent link="left_inner_knuckle" />
    <child link="left_inner_finger" />
    <axis xyz="0 -1 0" />
    <limit lower="0" upper="0.8757" velocity="2.0" effort="1000" />
    <mimic joint="finger_joint" multiplier="-1" offset="0" />
  </joint>
  <link name="right_inner_knuckle">
    <inertial>
      <origin xyz="0.0168606186773776 3.93808471820465E-10 0.0226699950793434" rpy="0 0 0" />
      <mass value="0.0110930853895903" />
      <inertia ixx="4.27134775939882E-06" ixy="-8.53568456728898E-15" ixz="1.77774229944246E-06" iyy="3.96548790524392E-06" iyz="-8.45108024914164E-15" izz="3.20325997634666E-06"/>
    </inertial>
    <visual>
      <origin xyz="0 0 0" rpy="0 0 0" />
      <geometry>
        <!-- <mesh filename="package://kimm_robotiq_2f_85_description/meshes/visual/robotiq_arg2f_85_inner_knuckle.dae" scale="0.001 0.001 0.001"/> -->
        <mesh filename="package://kimm_robotiq_2f_85_description/meshes_aprice/inner_knuckle_fine.STL"/>
      </geometry>
      <material name="">
        <color rgba="0.1 0.1 0.1 1" />
      </material>
    </visual>
    <collision>
      <origin xyz="0 0 0" rpy="0 0 0" />
      <geometry>
        <!-- <mesh filename="package://kimm_robotiq_2f_85_description/meshes/collision/robotiq_arg2f_85_inner_knuckle.dae" scale="0.001 0.001 0.001"/> -->
        <mesh filename="package://kimm_robotiq_2f_85_description/meshes_aprice/inner_knuckle_coarse.STL"/>
      </geometry>
    </collision>
  </link>
  <joint name="right_inner_knuckle_joint" type="revolute">
    <origin xyz="-0.0126999999998499 0 0.0693075000000361" rpy="0 0 3.14159265358979" />
    <parent link="robotiq_85_base_link" />
    <child link="right_inner_knuckle" />
    <axis xyz="0 1 0" />
    <limit lower="0" upper="0.8757" velocity="2.0" effort="1000" />
    <mimic joint="finger_joint" multiplier="-1" offset="0" />
  </joint>
  <link name="right_inner_finger">
    <inertial>
      <origin xyz="0.00602756228812038 -6.47284509480176E-15 0.00669925609578108" rpy="0 0 0" />
      <mass value="0.00724255346165744" />
      <inertia ixx="1.47824283625957E-06" ixy="-3.95952064019123E-19" ixz="-3.45268708875543E-07" iyy="1.70064480838394E-06" iyz="3.55286507960029E-19" izz="4.77151241114822E-07"/>
    </inertial>
    <visual>
      <origin xyz="0 0 0" rpy="0 0 0" />
      <geometry>
        <!-- <mesh filename="package://kimm_robotiq_2f_85_description/meshes/visual/robotiq_arg2f_85_inner_finger.dae" scale="0.001 0.001 0.001"/> -->
        <mesh filename="package://kimm_robotiq_2f_85_description/meshes_aprice/inner_finger_fine.STL"/>
      </geometry>
      <material name="">
        <color rgba="0.1 0.1 0.1 1" />
      </material>
    </visual>
    <collision>
      <origin xyz="0 0 0" rpy="0 0 0" />
      <geometry>
        <!-- <mesh filename="package://kimm_robotiq_2f_85_description/meshes/collision/robotiq_arg2f_85_inner_finger.dae" scale="0.001 0.001 0.001"/> -->
        <mesh filename="package://kimm_robotiq_2f_85_description/meshes_aprice/inner_finger_coarse.STL"/>
      </geometry>
    </collision>
  </link>
  <joint name="right_inner_finger_joint" type="revolute">
    <origin xyz="0.0341060475457406 0 0.0458573878541688" rpy="0 0 0" />
    <parent link="right_inner_knuckle" />
    <child link="right_inner_finger" />
    <axis xyz="0 1 0" />
    <limit lower="0" upper="0.8757" velocity="2.0" effort="1000" />
    <mimic joint="finger_joint" multiplier="1" offset="0" />
  </joint>
  <link name="right_outer_knuckle">
    <inertial>
      <origin xyz="0.0178097074051638 3.60493211424024E-11 0.00233123458346721" rpy="0 0 0" />
      <mass value="0.00684838849401352" />
      <inertia ixx="2.70004361573169E-07" ixy="1.59579467624491E-15" ixz="1.56396493788199E-07" iyy="1.38892332558312E-06" iyz="2.82357800318817E-15" izz="1.26286103637978E-06"/>
    </inertial>
    <visual>
      <origin xyz="0 0 0" rpy="0 0 0" />
      <geometry>
        <!-- <mesh filename="package://kimm_robotiq_2f_85_description/meshes/visual/robotiq_arg2f_85_outer_knuckle.dae" scale="0.001 0.001 0.001"/> -->
        <mesh filename="package://kimm_robotiq_2f_85_description/meshes_aprice/outer_knuckle_fine.STL"/>
      </geometry>
      <material name="">
        <color rgba="0.1 0.1 0.1 1" />
      </material>
    </visual>
    <collision>
      <origin xyz="0 0 0" rpy="0 0 0" />
      <geometry>
        <!-- <mesh filename="package://kimm_robotiq_2f_85_description/meshes/collision/robotiq_arg2f_85_outer_knuckle.dae" scale="0.001 0.001 0.001"/> -->
        <mesh filename="package://kimm_robotiq_2f_85_description/meshes_aprice/outer_knuckle_coarse.STL"/>
      </geometry>
    </collision>
  </link>
  <joint name="right_outer_knuckle_joint" type="revolute">
    <origin xyz="-0.0306011444258893 0 0.0627920162695395" rpy="0 0 3.14159265358979" />
    <parent link="robotiq_85_base_link" />
    <child link="right_outer_knuckle" />
    <axis xyz="0 1 0" />
    <limit lower="0" upper="0.8757" velocity="2.0" effort="1000" />
    <mimic joint="finger_joint" multiplier="-1" offset="0" />
  </joint>
  <link name="right_outer_finger">
    <inertial>
      <origin xyz="0.00108844269639009 -2.611488350845E-15 0.0215530225245502" rpy="0 0 0" />
      <mass value="0.0273093985570947" />
      <inertia ixx="8.52366028592721E-06" ixy="3.41683380899422E-19" ixz="3.18003675694284E-07" iyy="6.91333280651081E-06" iyz="7.37726682706417E-19" izz="2.24270431912283E-06"/>
    </inertial>
    <visual>
      <origin xyz="0 0 0" rpy="0 0 0" />
      <geometry>
        <!-- <mesh filename="package://kimm_robotiq_2f_85_description/meshes/visual/robotiq_arg2f_85_outer_finger.dae" scale="0.001 0.001 0.001"/> -->
        <mesh filename="package://kimm_robotiq_2f_85_description/meshes_aprice/outer_finger_fine.STL"/>
      </geometry>
      <material name="">
        <color rgba="0.1 0.1 0.1 1" />
      </material>
    </visual>
    <collision>
      <origin xyz="0 0 0" rpy="0 0 0" />
      <geometry>
        <!-- <mesh filename="package://kimm_robotiq_2f_85_description/meshes/collision/robotiq_arg2f_85_outer_finger.dae" scale="0.001 0.001 0.001"/> -->
        <mesh filename="package://kimm_robotiq_2f_85_description/meshes_aprice/outer_finger_coarse.STL"/>
      </geometry>
    </collision>
  </link>
  <joint name="right_outer_finger_joint" type="fixed">
    <origin xyz="0.0317095909367246 0 -0.0016013564954687" rpy="0 0 0" />
    <parent link="right_outer_knuckle" />
    <child link="right_outer_finger" />
    <axis xyz="0 1 0" />
  </joint>  

  <!-- CAMERA JIG-->
  <joint name="camera_jig_joint" type="fixed">
      <origin rpy="0.0 0.0 0" xyz="0.0 0 0.0" />
      <parent link="robotiq_85_base_link" />
      <child link="camera_jig_link" />
  </joint>
  <link name="camera_jig_link" />
      <inertial>          
          <mass value="0.328" />          
      </inertial>

  <!-- CAMERA -->
  <material name="camera_aluminum">
      <color rgba="0.5 0.5 0.5 1" />
  </material>
  <!-- camera body, with origin at bottom screw mount -->
  <joint name="camera_joint" type="fixed">      
      <origin rpy="3.14 -1.57 -1.57" xyz="0.0 -0.09 0.085" />
      <parent link="camera_jig_link" />
      <child link="camera_bottom_screw_frame" />
  </joint>
  <link name="camera_bottom_screw_frame" />
  <joint name="camera_link_joint" type="fixed">
      <origin rpy="0 0 0" xyz="0 0.0175 0.0125" />
      <parent link="camera_bottom_screw_frame" />
      <child link="camera_link" />
  </joint>
  <link name="camera_link">
      <visual>
          <origin rpy="1.57079632679 0 1.57079632679" xyz="0.0149 -0.0175 0" />
          <geometry>
              <!-- <box size="${d435_cam_width} ${d435_cam_height} ${d435_cam_depth}"/> -->
              <mesh filename="package://realsense2_description/meshes/d435.dae" />
          </geometry>
          <material name="camera_aluminum" />
      </visual>
      <collision>
          <origin rpy="0 0 0" xyz="0 -0.0175 0" />
          <geometry>
              <box size="0.02505 0.09 0.025" />
          </geometry>
      </collision>
      <inertial>
          <!-- The following are not reliable values, and should not be used for modeling -->
          <mass value="0.072" />
          <origin xyz="0 0 0" />
          <inertia ixx="0.003881243" ixy="0.0" ixz="0.0" iyy="0.000498940" iyz="0.0" izz="0.003879257" />
      </inertial>
  </link>
  <!-- camera depth joints and links -->
  <joint name="camera_depth_joint" type="fixed">
      <origin rpy="0 0 0" xyz="0 0 0" />
      <parent link="camera_link" />
      <child link="camera_depth_frame" />
  </joint>
  <link name="camera_depth_frame" />
  <joint name="camera_depth_optical_joint" type="fixed">
      <origin rpy="-1.57079632679 0 -1.57079632679" xyz="0 0 0" />
      <parent link="camera_depth_frame" />
      <child link="camera_depth_optical_frame" />
  </joint>
  <link name="camera_depth_optical_frame" />
  <!-- camera left IR joints and links -->
  <joint name="camera_left_ir_joint" type="fixed">
      <origin rpy="0 0 0" xyz="0 0.0 0" />
      <parent link="camera_depth_frame" />
      <child link="camera_left_ir_frame" />
  </joint>
  <link name="camera_left_ir_frame" />
  <joint name="camera_left_ir_optical_joint" type="fixed">
      <origin rpy="-1.57079632679 0 -1.57079632679" xyz="0 0 0" />
      <parent link="camera_left_ir_frame" />
      <child link="camera_left_ir_optical_frame" />
  </joint>
  <link name="camera_left_ir_optical_frame" />
  <!-- camera right IR joints and links -->
  <joint name="camera_right_ir_joint" type="fixed">
      <origin rpy="0 0 0" xyz="0 -0.05 0" />
      <parent link="camera_depth_frame" />
      <child link="camera_right_ir_frame" />
  </joint>
  <link name="camera_right_ir_frame" />
  <joint name="camera_right_ir_optical_joint" type="fixed">
      <origin rpy="-1.57079632679 0 -1.57079632679" xyz="0 0 0" />
      <parent link="camera_right_ir_frame" />
      <child link="camera_right_ir_optical_frame" />
  </joint>
  <link name="camera_right_ir_optical_frame" />
  <!-- camera color joints and links -->
  <joint name="camera_color_joint" type="fixed">
      <origin rpy="0 0 0" xyz="0 0.015 0" />
      <parent link="camera_depth_frame" />
      <child link="camera_color_frame" />
  </joint>
  <link name="camera_color_frame" />
  <joint name="camera_color_optical_joint" type="fixed">
      <origin rpy="-1.57079632679 0 -1.57079632679" xyz="0 0 0" />
      <parent link="camera_color_frame" />
      <child link="camera_color_optical_frame" />
  </joint>
  <link name="camera_color_optical_frame" />
</robot>

