<mujoco model="panda">
    <compiler angle="radian" />
    <size njmax="500" nconmax="100" />
    <asset>
        <mesh name="link0" file="../meshes/visual/link0.stl" />
        <mesh name="link1" file="../meshes/visual/link1.stl" />
        <mesh name="link2" file="../meshes/visual/link2.stl" />
        <mesh name="link3" file="../meshes/visual/link3.stl" />
        <mesh name="link4" file="../meshes/visual/link4.stl" />
        <mesh name="link5" file="../meshes/visual/link5.stl" />
        <mesh name="link6" file="../meshes/visual/link6.stl" />
        <mesh name="link7" file="../meshes/visual/link7.stl" />
        <mesh name="robotiq_85_base_link_coarse" file="../meshes/visual/robotiq_85_base_link_coarse.STL" />
        <mesh name="outer_knuckle_coarse" file="../meshes/visual/outer_knuckle_coarse.STL" />
        <mesh name="outer_finger_coarse" file="../meshes/visual/outer_finger_coarse.STL" />
        <mesh name="inner_knuckle_coarse" file="../meshes/visual/inner_knuckle_coarse.STL" />
        <mesh name="inner_finger_coarse" file="../meshes/visual/inner_finger_coarse.STL" />
    </asset>
    <worldbody>
        <body name="l_panda_link0" pos="0.0 0 0.0">
            <geom type="mesh" mesh="link0" rgba=".95 .99 .92 1"/>
        <body name="panda_link1" pos="0 0 0.333">
            <inertial pos="0.003875 0.002081 -0.175" quat="0.711549 0.00634377 -0.0131124 0.702485" mass="4.97068" diaginertia="0.707137 0.703435 0.00852456" />
            <joint name="panda_joint1" pos="0 0 0" axis="0 0 1" limited="true" range="-2.8973 2.8973" damping="10" frictionloss="5" />
            <geom type="mesh" mesh="link1" rgba=".95 .99 .92 1"/>
            <body name="panda_link2" pos="0 0 0" quat="0.707107 -0.707107 0 0">
                <inertial pos="-0.003141 -0.02872 0.003495" quat="-0.168175 0.828366 -0.122878 0.520027" mass="0.646926" diaginertia="0.0310326 0.0283001 0.00273425" />
                <joint name="panda_joint2" pos="0 0 0" axis="0 0 1" limited="true" range="-1.7628 1.7628" damping="5" frictionloss="2" />
                <geom type="mesh" mesh="link2" rgba=".95 .99 .92 1"/>
                <body name="panda_link3" pos="0 -0.316 0" quat="0.707107 0.707107 0 0">
                    <inertial pos="0.027518 0.039252 -0.066502" quat="0.662769 -0.00678331 0.252053 0.705096" mass="3.2286" diaginertia="0.0415014 0.0414793 0.00124635" />
                    <joint name="panda_joint3" pos="0 0 0" axis="0 0 1" limited="true" range="-2.8973 2.8973" damping="5" frictionloss="2" />
                    <geom type="mesh" mesh="link3" rgba=".95 .99 .92 1"/>
                    <body name="panda_link4" pos="0.0825 0 0" quat="0.707107 0.707107 0 0">
                        <inertial pos="-0.05317 0.104419 0.027454" quat="0.65058 0.529822 -0.0962034 0.535518" mass="3.5879" diaginertia="0.0349596 0.0281483 0.0106201" />
                        <joint name="panda_joint4" pos="0 0 0" axis="0 0 1" limited="true" range="-3.0718 -0.0698" damping="1" frictionloss="0.5" />
                        <geom type="mesh" mesh="link4" rgba=".95 .99 .92 1"/>
                        <body name="panda_link5" pos="-0.0825 0.384 0" quat="0.707107 -0.707107 0 0">
                            <inertial pos="-0.011953 0.041065 -0.038437" quat="0.987313 -0.0121954 0.0719187 -0.141037" mass="1.22595" diaginertia="0.0367625 0.0288531 0.00803437" />
                            <joint name="panda_joint5" pos="0 0 0" axis="0 0 1" limited="true" range="-2.8973 2.8973" damping="2" frictionloss="1" />
                            <geom type="mesh" mesh="link5" rgba=".95 .99 .92 1"/>
                            <body name="panda_link6" pos="0 0 0" quat="0.707107 0.707107 0 0">
                                <inertial pos="0.060149 -0.014117 -0.010517" quat="0.101075 0.59332 0.0287227 0.798079" mass="1.66656" diaginertia="0.00584276 0.00431037 0.00159787" />
                                <joint name="panda_joint6" pos="0 0 0" axis="0 0 1" limited="true" range="-0.0175 3.7525" damping="1" frictionloss="0.5" />
                                <geom type="mesh" mesh="link6" rgba=".95 .99 .92 1"/>
                                <body name="panda_link7" pos="0.088 0 0" quat="0.707107 0.707107 0 0">
                                    <inertial pos="0.00733449 -0.00290087 0.0841777" quat="0.994565 -0.0665484 0.053538 -0.0595372" mass="1.05467" diaginertia="0.0152311 0.0126575 0.00582013" />
                                    <joint name="panda_joint7" pos="0 0 0" axis="0 0 1" limited="true" range="-2.8973 2.8973" damping="1" frictionloss="0.5" />
                                    <geom type="mesh" mesh="link7" rgba=".95 .99 .92 1"/>
                                    <geom pos="0 0 0.107" quat="0.707107 0 0 0.707107" type="mesh" rgba="0.1 0.1 0.1 1" mesh="robotiq_85_base_link_coarse" />
                                    <body name="left_outer_knuckle" pos="0 0.0306011 0.169792" quat="0.707107 0 0 0.707107">
                                        <inertial pos="0.0299636 7.39879e-12 0.0161054" quat="0.704933 0.0554073 0.0554073 0.704933" mass="0.0341578" diaginertia="1.12323e-05 1.05984e-05 4.63087e-06" />
                                        <joint name="left_outer_knuckle_joint" pos="0 0 0" axis="0 -1 0" limited="true" range="0 0.725" />
                                        <geom type="mesh" rgba="0.1 0.1 0.1 1" mesh="outer_knuckle_coarse" />
                                        <geom pos="0.031691 0 -0.00193396" type="mesh" rgba="0.1 0.1 0.1 1" mesh="outer_finger_coarse" />
                                    </body> 
                                    <body name="left_inner_knuckle" pos="0 0.0127 0.176307" quat="0.707107 0 0 0.707107">
                                        <inertial pos="0.0170975 -3.93809e-10 0.0224918" quat="0.947655 0 -0.319297 0" mass="0.0110931" diaginertia="5.59353e-06 3.96549e-06 1.88108e-06" />
                                        <joint name="left_inner_knuckle_joint" pos="0 0 0" axis="0 -1 0" limited="true" range="0 0.8757" />
                                        <geom type="mesh" rgba="0.1 0.1 0.1 1" mesh="inner_knuckle_coarse" />
                                        <body name="left_inner_finger" pos="0.0345853 0 0.045497">
                                            <inertial pos="0.00602756 0 0.00669926" quat="0.699065 0.106339 0.106339 0.699065" mass="0.00724255" diaginertia="1.70064e-06 1.58577e-06 3.69621e-07" />
                                            <joint name="left_inner_finger_joint" pos="0 0 0" axis="0 -1 0" limited="true" range="0 0.8757" />
                                            <geom type="mesh" rgba="0.1 0.1 0.1 1" mesh="inner_finger_coarse" />
                                        </body>
                                    </body>
                                    <body name="right_inner_knuckle" pos="0 -0.0127 0.176308" quat="-0.707107 0 0 0.707107">
                                        <inertial pos="0.0168606 3.93808e-10 0.02267" quat="0.949317 0 -0.314322 0" mass="0.0110931" diaginertia="5.59353e-06 3.96549e-06 1.88108e-06" />
                                        <joint name="right_inner_knuckle_joint" pos="0 0 0" axis="0 1 0" limited="true" range="0 0.8757" />
                                        <geom type="mesh" rgba="0.1 0.1 0.1 1" mesh="inner_knuckle_coarse" />
                                        <body name="right_inner_finger" pos="0.034106 0 0.0458574">
                                            <inertial pos="0.00602756 0 0.00669926" quat="0.699065 0.106339 0.106339 0.699065" mass="0.00724255" diaginertia="1.70064e-06 1.58577e-06 3.69621e-07" />
                                            <joint name="right_inner_finger_joint" pos="0 0 0" axis="0 1 0" limited="true" range="0 0.8757" />
                                            <geom type="mesh" rgba="0.1 0.1 0.1 1" mesh="inner_finger_coarse"/>
                                        </body>
                                    </body>
                                    <body name="right_outer_knuckle" pos="0 -0.0306011 0.169792" quat="-0.707107 0 0 0.707107">
                                        <inertial pos="0.029793 7.22554e-12 0.0164189" quat="0.704767 0.057475 0.057475 0.704767" mass="0.0341578" diaginertia="1.12323e-05 1.06532e-05 4.57606e-06" />
                                        <joint name="right_outer_knuckle_joint" pos="0 0 0" axis="0 1 0" limited="true" range="0 0.8757" />
                                        <geom type="mesh" rgba="0.1 0.1 0.1 1" mesh="outer_knuckle_coarse"/>
                                        <geom pos="0.0317096 0 -0.00160136" type="mesh" rgba="0.1 0.1 0.1 1" mesh="outer_finger_coarse" />
                                    </body>
                                </body>
                            </body>
                        </body>
                    </body>
                </body>
            </body>
        </body>
        </body>
    </worldbody>

    <actuator>
        <motor name="panda_joint1_Motor" joint="panda_joint1"/>
        <motor name="panda_joint2_Motor" joint="panda_joint2"/>
        <motor name="panda_joint3_Motor" joint="panda_joint3"/>
        <motor name="panda_joint4_Motor" joint="panda_joint4"/>
        <motor name="panda_joint5_Motor" joint="panda_joint5"/>
        <motor name="panda_joint6_Motor" joint="panda_joint6"/>
        <motor name="panda_joint7_Motor" joint="panda_joint7"/>
        <motor name="left_outer_knuckle_joint"   joint="left_outer_knuckle_joint"/>        
        <motor name="left_inner_knuckle_joint"   joint="left_inner_knuckle_joint"/>        
        <motor name="left_inner_finger_joint"   joint="left_inner_finger_joint"/>        
        <motor name="right_inner_knuckle_joint"   joint="right_inner_knuckle_joint"/>        
        <motor name="right_inner_finger_joint"   joint="right_inner_finger_joint"/>        
        <motor name="right_outer_knuckle_joint"   joint="right_outer_knuckle_joint"/>        
    </actuator>
</mujoco>
