<mujoco model="panda">
    <compiler angle="radian" />
    <size njmax="500" nconmax="100" />
    <default>
        <default class="FTsensor">
            <site type="cylinder" size="0.005 0.005" group="4" rgba=".1 .1 .9 1"/>
        </default>
    </default>
    <default>   
        <default class="cls">
                <geom group="1" rgba="0.79216 0.81961 0.93333 0.5"/>
        </default>
    </default>
    <asset>
        <mesh name="l_link0" file="link0.stl" />
        <mesh name="l_link1" file="link1.stl" />
        <mesh name="l_link2" file="link2.stl" />
        <mesh name="l_link3" file="link3.stl" />
        <mesh name="l_link4" file="link4.stl" />
        <mesh name="l_link5" file="link5.stl" />
        <mesh name="l_link6" file="link6.stl" />
        <mesh name="l_link7" file="link7.stl" />
    </asset>
    <worldbody>
        <body name="l_panda_link0" pos="-1.0 0 0.0">
        <geom type="mesh" mesh="l_link0" rgba=".95 .99 .92 1" />
        <body name="l_panda_link1" pos="-0.0 0 0.333">
            <inertial pos="0.003875 0.002081 -0.175" quat="0.711549 0.00634377 -0.0131124 0.702485" mass="4.97068" diaginertia="0.707137 0.703435 0.00852456" />
            <joint name="l_panda_joint1" pos="0 0 0" axis="0 0 1" limited="true" range="-2.8973 2.8973" damping="1" frictionloss="1" />
            <geom type="mesh" mesh="l_link1"rgba=".95 .99 .92 1" />
            <body name="l_panda_link2" pos="0 0 0" quat="0.707107 -0.707107 0 0">
                <inertial pos="-0.003141 -0.02872 0.003495" quat="-0.168175 0.828366 -0.122878 0.520027" mass="0.646926" diaginertia="0.0310326 0.0283001 0.00273425" />
                <joint name="l_panda_joint2" pos="0 0 0" axis="0 0 1" limited="true" range="-1.7628 1.7628" damping="1" frictionloss="1" />
                <geom type="mesh" mesh="l_link2" rgba=".95 .99 .92 1" />
                <body name="l_panda_link3" pos="0 -0.316 0" quat="0.707107 0.707107 0 0">
                    <inertial pos="0.027518 0.039252 -0.066502" quat="0.662769 -0.00678331 0.252053 0.705096" mass="3.2286" diaginertia="0.0415014 0.0414793 0.00124635" />
                    <joint name="l_panda_joint3" pos="0 0 0" axis="0 0 1" limited="true" range="-2.8973 2.8973" damping="1" frictionloss="1" />
                    <geom type="mesh" mesh="l_link3" rgba=".95 .99 .92 1" />
                    <body name="l_panda_link4" pos="0.0825 0 0" quat="0.707107 0.707107 0 0">
                        <inertial pos="-0.05317 0.104419 0.027454" quat="0.65058 0.529822 -0.0962034 0.535518" mass="3.5879" diaginertia="0.0349596 0.0281483 0.0106201" />
                        <joint name="l_panda_joint4" pos="0 0 0" axis="0 0 1" limited="true" range="-3.0718 -0.0698" damping="1" frictionloss="1" />
                        <geom type="mesh" mesh="l_link4" rgba=".95 .99 .92 1" />
                        <body name="l_panda_link5" pos="-0.0825 0.384 0" quat="0.707107 -0.707107 0 0">
                            <inertial pos="-0.011953 0.041065 -0.038437" quat="0.987313 -0.0121954 0.0719187 -0.141037" mass="1.22595" diaginertia="0.0367625 0.0288531 0.00803437" />
                            <joint name="l_panda_joint5" pos="0 0 0" axis="0 0 1" limited="true" range="-2.8973 2.8973" damping="1" frictionloss="1" />
                            <geom type="mesh" mesh="l_link5" rgba=".95 .99 .92 1" />
                            <body name="l_panda_link6" pos="0 0 0" quat="0.707107 0.707107 0 0">
                                <inertial pos="0.060149 -0.014117 -0.010517" quat="0.101075 0.59332 0.0287227 0.798079" mass="1.66656" diaginertia="0.00584276 0.00431037 0.00159787" />
                                <joint name="l_panda_joint6" pos="0 0 0" axis="0 0 1" limited="true" range="-0.0175 3.7525" damping="1" frictionloss="1" />
                                <geom type="mesh" mesh="l_link6" rgba=".95 .99 .92 1" />
                                <body name="l_panda_link7" pos="0.088 0 0" quat="0.707107 0.707107 0 0">
                                    <inertial pos="0.010517 -0.004252 0.061597" quat="0.992939 -0.0762041 0.0733595 -0.0537067" mass="0.735522" diaginertia="0.0127345 0.0101055 0.00451803" />
                                    <joint name="l_panda_joint7" pos="0 0 0" axis="0 0 1" limited="true" range="-2.8973 2.8973" damping="1" frictionloss="1" />
                                    <geom type="mesh" mesh="l_link7" rgba=".95 .99 .92 1" />
                                    <geom class="cls" size="0.05 0.0135" pos="0.00 0 0.11"  friction="1.0 1.0 1.0" type="cylinder"/>
                                    <site class="FTsensor" name="l_FTsensor" pos="0 0 0.05"/>
                                </body>
                            </body>
                        </body>
                    </body>
                </body>
            </body>
        </body>
        </body>
    </worldbody>
    <actuator>
        <motor name="l_panda_joint1_Motor" joint="l_panda_joint1"/>
        <motor name="l_panda_joint2_Motor" joint="l_panda_joint2"/>
        <motor name="l_panda_joint3_Motor" joint="l_panda_joint3"/>
        <motor name="l_panda_joint4_Motor" joint="l_panda_joint4"/>
        <motor name="l_panda_joint5_Motor" joint="l_panda_joint5"/>
        <motor name="l_panda_joint6_Motor" joint="l_panda_joint6"/>
        <motor name="l_panda_joint7_Motor" joint="l_panda_joint7"/>
    </actuator>
    <sensor>
        <force name="l_force" site="l_FTsensor"/>
        <torque name="l_torque" site="l_FTsensor"/>
    </sensor>
</mujoco>
